<?xml version="1.0" encoding="UTF-8"?>
<testsuite errors="1" failures="2" name="application.tests.TestApi-20171222144644" skipped="0" tests="4" time="1.268">
	<testcase classname="application.tests.TestApi" name="test_badOrderRequest2" time="0.047"/>
	<testcase classname="application.tests.TestApi" name="test_badOrderRequest" time="0.281">
		<failure message="401 != 400" type="AssertionError">
<![CDATA[Traceback (most recent call last):
  File "C:\Users\stylesm\Desktop\test\OFS-MORE-Beta-Secured\source\payment_gateway\application\tests.py", line 44, in test_badOrderRequest
    self.assertEqual(response.status_code, 400)
AssertionError: 401 != 400
]]>		</failure>
	</testcase>
	<testcase classname="application.tests.TestApi" name="test_orderRequest" time="0.172">
		<failure message="401 != 200" type="AssertionError">
<![CDATA[Traceback (most recent call last):
  File "C:\Users\stylesm\Desktop\test\OFS-MORE-Beta-Secured\source\payment_gateway\application\tests.py", line 27, in test_orderRequest
    self.assertEqual(response.status_code, 200)
AssertionError: 401 != 200
]]>		</failure>
	</testcase>
	<testcase classname="application.tests.TestApi" name="test_badAPIOrderRequest" time="0.769">
		<error message="'Settings' object has no attribute 'NOTIFY_API'" type="AttributeError">
<![CDATA[Traceback (most recent call last):
  File "C:\Users\stylesm\Desktop\test\OFS-MORE-Beta-Secured\source\payment_gateway\application\tests.py", line 86, in test_badAPIOrderRequest
    "apiKey": settings.NOTIFY_API
  File "C:\Python 3.5\lib\site-packages\django\conf\__init__.py", line 57, in __getattr__
    val = getattr(self._wrapped, name)
AttributeError: 'Settings' object has no attribute 'NOTIFY_API'
]]>		</error>
	</testcase>
	<system-out>
<![CDATA[]]>	</system-out>
	<system-err>
<![CDATA[]]>	</system-err>
</testsuite>
