<?xml version="1.0" encoding="UTF-8"?>
<testsuite errors="0" failures="1" name="application.tests.TestApi-20180108160627" skipped="0" tests="6" time="1.791">
	<testcase classname="application.tests.TestApi" name="test_getOrderInfo" time="0.944"/>
	<testcase classname="application.tests.TestApi" name="test_getOrderInfoError" time="0.200"/>
	<testcase classname="application.tests.TestApi" name="test_serializerError" time="0.059"/>
	<testcase classname="application.tests.TestApi" name="test_setApiKey" time="0.005"/>
	<testcase classname="application.tests.TestApi" name="test_worldpayError" time="0.158"/>
	<testcase classname="application.tests.TestApi" name="test_orderRequest" time="0.425">
		<failure message="201 != 200" type="AssertionError">
<![CDATA[Traceback (most recent call last):
  File "C:\Users\stylesm\Desktop\test\OFS-MORE-Beta-Secured\source\payment_gateway\application\tests.py", line 30, in test_orderRequest
    self.assertEqual(response.status_code, 200)
AssertionError: 201 != 200
]]>		</failure>
	</testcase>
	<system-out>
<![CDATA[]]>	</system-out>
	<system-err>
<![CDATA[]]>	</system-err>
</testsuite>
